Workbook

Sheet README
B2: Fingerprint Device Inventory & Classification System
B3: Master Workbook — auto-classifies every device into its correct storage box
B5: 1) How to Use This Workbook — Overview
B7: This master workbook automatically inspects every device record and assigns it to the correct physical storage box, based on the fault keywords found in the form responses.
B10: The moment a row is entered on the "All Devices (Master)" sheet, its Assigned Box is calculated automatically by formula — and it instantly appears on the matching Box sheet too. No copy-pasting required.
B13: 2) Box Definitions
B14: Box W — Fully working units — zero faults, ready to deploy
B15: Box D1–D4 — Display-fault units, spread across 4 boxes by capacity
B16: Box S1 — Sensor fault / missing fingerprint sensor
B17: Box K1 — Keypad / keyboard faults
B18: Box P1 — Power-related issues (no supply, auto shut-off)
B19: Box U1 — Unclassified, needs manual inspection, or donor/scrap unit
... B68: Generated automatically from the Google Form response export. Prepared for internal office use — Component Testing & Sorting Unit.

Sheet Dashboard
B2: Inventory Dashboard
B4: Total Devices Logged: | C4: =COUNTIF('All Devices (Master)'!$B$3:$B$252,"<>") -> 144
B5: Devices Needing Attention (Notes flagged): | C5: =COUNTIF('All Devices (Master)'!$V$3:$V$252,"?*") -> 25
B6: Last Response Received: | C6: =MAX('All Devices (Master)'!$B$3:$B$252) -> 46246.49
B8: Box | C8: Description | D8: Count | E8: % of Total
B9: W | C9: Fully working | D9: =COUNTIF('All Devices (Master)'!$T$3:$T$252,$B9) -> 80 | E9: =IFERROR(D9/COUNTIF('All Devices (Master)'!$B$3:$B$252,"<>"),0) -> 0.55555556
B10: D1 | C10: Display fault - group 1 | D10: =COUNTIF('All Devices (Master)'!$T$3:$T$252,$B10) -> 7 | E10: =IFERROR(D10/COUNTIF('All Devices (Master)'!$B$3:$B$252,"<>"),0) -> 0.048611111
B11: D2 | C11: Display fault - group 2 | D11: =COUNTIF('All Devices (Master)'!$T$3:$T$252,$B11) -> 7 | E11: =IFERROR(D11/COUNTIF('All Devices (Master)'!$B$3:$B$252,"<>"),0) -> 0.048611111
B12: D3 | C12: Display fault - group 3 | D12: =COUNTIF('All Devices (Master)'!$T$3:$T$252,$B12) -> 7 | E12: =IFERROR(D12/COUNTIF('All Devices (Master)'!$B$3:$B$252,"<>"),0) -> 0.048611111
B13: D4 | C13: Display fault - group 4 | D13: =COUNTIF('All Devices (Master)'!$T$3:$T$252,$B13) -> 6 | E13: =IFERROR(D13/COUNTIF('All Devices (Master)'!$B$3:$B$252,"<>"),0) -> 0.041666667
B14: S1 | C14: Sensor fault or missing | D14: =COUNTIF('All Devices (Master)'!$T$3:$T$252,$B14) -> 26 | E14: =IFERROR(D14/COUNTIF('All Devices (Master)'!$B$3:$B$252,"<>"),0) -> 0.18055556
B15: K1 | C15: Keypad fault | D15: =COUNTIF('All Devices (Master)'!$T$3:$T$252,$B15) -> 3 | E15: =IFERROR(D15/COUNTIF('All Devices (Master)'!$B$3:$B$252,"<>"),0) -> 0.020833333
B16: P1 | C16: Power issues | D16: =COUNTIF('All Devices (Master)'!$T$3:$T$252,$B16) -> 4 | E16: =IFERROR(D16/COUNTIF('All Devices (Master)'!$B$3:$B$252,"<>"),0) -> 0.027777778
B17: U1 | C17: Unclassified, needs review, or donor unit | D17: =COUNTIF('All Devices (Master)'!$T$3:$T$252,$B17) -> 4 | E17: =IFERROR(D17/COUNTIF('All Devices (Master)'!$B$3:$B$252,"<>"),0) -> 0.027777778
B18: TOTAL | D18: =SUM(D9:D17) -> 144 | E18: =SUM(E9:E17) -> 1

Sheet Settings
B2: Settings & Configuration
B4: Display Box Capacity (units per D box): | C4: 7 | D4: ← edit this number to rebalance D1–D4
B6: Fault Classification Keywords
B7: Category | C7: Keyword (add new rows within a category block to sharpen matching)
B8: Sensor | C8: sensor
B9: Sensor | C9: finger print scanner
B10: Sensor | C10: fingerprint scanner
B11: Display | C11: display
B12: Keypad | C12: keypad
B13: Keypad | C13: key pad
B14: Keypad | C14: key board
B15: Keypad | C15: keyboard
B16: Keypad | C16: keys
B17: Power | C17: power
B18: Power | C18: turn on
... B24: Empty | C24: emty
B26: Model Name Standardization
B27: Original (as typed on form) | C27: Standardized Name
B28: X628 | C28: X628
B29: X-628 | C29: X628
B30: TX628 | C30: TX628
B31: X628-C | C31: X628-C
B32: X628 Plus | C32: X628 Plus
B33: Iclock3000 | C33: iClock3000
B34: iClock700 | C34: iClock700
B35: SlikFP 100TA | C35: SlikFP 100TA
B36: G1 | C36: G1
B37: K14 | C37: K14

Sheet All Devices (Master)
A1: All Devices — Master Data & Auto-Classification
A2: No. | B2: Timestamp | C2: Model Name (Original) | D2: Model Name (Standardized) | E2: Location | F2: Serial No | G2: Working Statement | H2: Fault (If any) | I2: Remark (Other Informations) | J2: Display Colour | K2: Combined Text | L2: Sensor Fault? | M2: Display Fault? | N2: Keypad Fault? | O2: Power Fault? | P2: Speaker Fault? | Q2: Empty / No Device? | R2: Needs Attention? | S2: Display Rank | T2: Assigned Box | U2: Sort Key | V2: Notes / QC Flags | W2: Score (Form) | X2: Email Address (Form)
A3: 1 | B3: 46239.469 | C3: X628 | D3: =IF($B3="","",IFERROR(VLOOKUP(TRIM($C3),ModelMap,2,FALSE()),TRIM($C3))) -> X628 | E3: Kandy 02 | F3: A5SA182160003 | G3: Working, No Power Supply | J3: Black & White | K3: =IF($B3="","",LOWER(TRIM($G3)&" | "&TRIM($H3)&" | "&TRIM($I3))) -> working, no power supply | | | L3: =IF($B3="","",SUMPRODUCT(--ISNUMBER(SEARCH(SensorKW,$K3)))>0) -> FALSE | M3: =IF($B3="","",SUMPRODUCT(--ISNUMBER(SEARCH(DisplayKW,$K3)))>0) -> FALSE | N3: =IF($B3="","",SUMPRODUCT(--ISNUMBER(SEARCH(KeypadKW,$K3)))>0) -> FALSE | O3: =IF($B3="","",SUMPRODUCT(--ISNUMBER(SEARCH(PowerKW,$K3)))>0) -> TRUE | P3: =IF($B3="","",SUMPRODUCT(--ISNUMBER(SEARCH(SpeakerKW,$K3)))>0) -> FALSE | Q3: =IF($B3="","",OR(SUMPRODUCT(--ISNUMBER(SEARCH(EmptyKW,$K3)))>0,LOWER(TRIM($F3))="empty")) -> FALSE | R3: =IF($B3="","",OR(ISNUMBER(SEARCH("repair",$G3)),ISNUMBER(SEARCH("not working",$G3)))) -> FALSE | S3: =IF(AND($B3<>"",$M3=TRUE(),$L3=FALSE(),$Q3=FALSE()),COUNTIFS($M$3:$M3,TRUE(),$L$3:$L3,FALSE(),$Q$3:$Q3,FALSE()),"") | T3: =IF($B3="","",IF($Q3=TRUE(),"U1",IF($L3=TRUE(),"S1",IF($M3=TRUE(),"D"&MIN(4,INT(($S3-1)/DisplayCapacity)+1),IF($N3=TRUE(),"K1",IF($O3=TRUE(),"P1",IF($P3=TRUE(),"U1",IF($R3=TRUE(),"U1","W")))))))) -> P1 | U3: =IF($T3="","",$T3&"-"&COUNTIF($T$3:T3,$T3)) -> P1-1 | V3: =IF($B3="","",_xlfn.TEXTJOIN(" | ",TRUE(),IF($Q3=TRUE(),"Empty box - no physical device, verify status",""),IF(AND($P3=TRUE(),$L3=FALSE(),$M3=FALSE(),$N3=FALSE(),$O3=FALSE(),$Q3=FALSE()),"Speaker fault only - needs manual box assignment",""),IF(AND($R3=TRUE(),$L3=FALSE(),$M3=FALSE(),$N3=FALSE(),$O3=FALSE(),$P3=FALSE(),$Q3=FALSE()),"No fault detail given - needs technician inspection",""),IF(AND(COUNTIF($F$3:$F$252,$F3)>1,LOWER(TRIM($F3))<>"empty"),"Duplicate Serial No - verify device identity",""),IF((--$L3+--$M3+--$N3+--$O3+--$P3)>1,"Multiple fault types detected - review full details before repair",""))) | W3: 0
A4: 2 | B4: 46239.476 | C4: X628 | D4: =IF($B4="","",IFERROR(VLOOKUP(TRIM($C4),ModelMap,2,FALSE()),TRIM($C4))) -> X628 | E4: Kandy 03 | F4: 6335173400003 | G4: Working | J4: Colour | K4: =IF($B4="","",LOWER(TRIM($G4)&" | "&TRIM($H4)&" | "&TRIM($I4))) -> working | | | L4: =IF($B4="","",SUMPRODUCT(--ISNUMBER(SEARCH(SensorKW,$K4)))>0) -> FALSE | M4: =IF($B4="","",SUMPRODUCT(--ISNUMBER(SEARCH(DisplayKW,$K4)))>0) -> FALSE | N4: =IF($B4="","",SUMPRODUCT(--ISNUMBER(SEARCH(KeypadKW,$K4)))>0) -> FALSE | O4: =IF($B4="","",SUMPRODUCT(--ISNUMBER(SEARCH(PowerKW,$K4)))>0) -> FALSE | P4: =IF($B4="","",SUMPRODUCT(--ISNUMBER(SEARCH(SpeakerKW,$K4)))>0) -> FALSE | Q4: =IF($B4="","",OR(SUMPRODUCT(--ISNUMBER(SEARCH(EmptyKW,$K4)))>0,LOWER(TRIM($F4))="empty")) -> FALSE | R4: =IF($B4="","",OR(ISNUMBER(SEARCH("repair",$G4)),ISNUMBER(SEARCH("not working",$G4)))) -> FALSE | S4: =IF(AND($B4<>"",$M4=TRUE(),$L4=FALSE(),$Q4=FALSE()),COUNTIFS($M$3:$M4,TRUE(),$L$3:$L4,FALSE(),$Q$3:$Q4,FALSE()),"") | T4: =IF($B4="","",IF($Q4=TRUE(),"U1",IF($L4=TRUE(),"S1",IF($M4=TRUE(),"D"&MIN(4,INT(($S4-1)/DisplayCapacity)+1),IF($N4=TRUE(),"K1",IF($O4=TRUE(),"P1",IF($P4=TRUE(),"U1",IF($R4=TRUE(),"U1","W")))))))) -> W | U4: =IF($T4="","",$T4&"-"&COUNTIF($T$3:T4,$T4)) -> W-1 | V4: =IF($B4="","",_xlfn.TEXTJOIN(" | ",TRUE(),IF($Q4=TRUE(),"Empty box - no physical device, verify status",""),IF(AND($P4=TRUE(),$L4=FALSE(),$M4=FALSE(),$N4=FALSE(),$O4=FALSE(),$Q4=FALSE()),"Speaker fault only - needs manual box assignment",""),IF(AND($R4=TRUE(),$L4=FALSE(),$M4=FALSE(),$N4=FALSE(),$O4=FALSE(),$P4=FALSE(),$Q4=FALSE()),"No fault detail given - needs technician inspection",""),IF(AND(COUNTIF($F$3:$F$252,$F4)>1,LOWER(TRIM($F4))<>"empty"),"Duplicate Serial No - verify device identity",""),IF((--$L4+--$M4+--$N4+--$O4+--$P4)>1,"Multiple fault types detected - review full details before repair",""))) | W4: 0
A5: 3 | B5: 46239.482 | C5: X628 | D5: =IF($B5="","",IFERROR(VLOOKUP(TRIM($C5),ModelMap,2,FALSE()),TRIM($C5))) -> X628 | E5: Kandy - KCC | F5: 6006144100022 | G5: Working | J5: Black & White | K5: =IF($B5="","",LOWER(TRIM($G5)&" | "&TRIM($H5)&" | "&TRIM($I5))) -> working | | | L5: =IF($B5="","",SUMPRODUCT(--ISNUMBER(SEARCH(SensorKW,$K5)))>0) -> FALSE | M5: =IF($B5="","",SUMPRODUCT(--ISNUMBER(SEARCH(DisplayKW,$K5)))>0) -> FALSE | N5: =IF($B5="","",SUMPRODUCT(--ISNUMBER(SEARCH(KeypadKW,$K5)))>0) -> FALSE | O5: =IF($B5="","",SUMPRODUCT(--ISNUMBER(SEARCH(PowerKW,$K5)))>0) -> FALSE | P5: =IF($B5="","",SUMPRODUCT(--ISNUMBER(SEARCH(SpeakerKW,$K5)))>0) -> FALSE | Q5: =IF($B5="","",OR(SUMPRODUCT(--ISNUMBER(SEARCH(EmptyKW,$K5)))>0,LOWER(TRIM($F5))="empty")) -> FALSE | R5: =IF($B5="","",OR(ISNUMBER(SEARCH("repair",$G5)),ISNUMBER(SEARCH("not working",$G5)))) -> FALSE | S5: =IF(AND($B5<>"",$M5=TRUE(),$L5=FALSE(),$Q5=FALSE()),COUNTIFS($M$3:$M5,TRUE(),$L$3:$L5,FALSE(),$Q$3:$Q5,FALSE()),"") | T5: =IF($B5="","",IF($Q5=TRUE(),"U1",IF($L5=TRUE(),"S1",IF($M5=TRUE(),"D"&MIN(4,INT(($S5-1)/DisplayCapacity)+1),IF($N5=TRUE(),"K1",IF($O5=TRUE(),"P1",IF($P5=TRUE(),"U1",IF($R5=TRUE(),"U1","W")))))))) -> W | U5: =IF($T5="","",$T5&"-"&COUNTIF($T$3:T5,$T5)) -> W-2 | V5: =IF($B5="","",_xlfn.TEXTJOIN(" | ",TRUE(),IF($Q5=TRUE(),"Empty box - no physical device, verify status",""),IF(AND($P5=TRUE(),$L5=FALSE(),$M5=FALSE(),$N5=FALSE(),$O5=FALSE(),$Q5=FALSE()),"Speaker fault only - needs manual box assignment",""),IF(AND($R5=TRUE(),$L5=FALSE(),$M5=FALSE(),$N5=FALSE(),$O5=FALSE(),$P5=FALSE(),$Q5=FALSE()),"No fault detail given - needs technician inspection",""),IF(AND(COUNTIF($F$3:$F$252,$F5)>1,LOWER(TRIM($F5))<>"empty"),"Duplicate Serial No - verify device identity",""),IF((--$L5+--$M5+--$N5+--$O5+--$P5)>1,"Multiple fault types detected - review full details before repair",""))) | W5: 0
A6: 4 | B6: 46239.495 | C6: X628 | D6: =IF($B6="","",IFERROR(VLOOKUP(TRIM($C6),ModelMap,2,FALSE()),TRIM($C6))) -> X628 | E6: Kegalle | F6: 6006171200007 | G6: Working | J6: Black & White | K6: =IF($B6="","",LOWER(TRIM($G6)&" | "&TRIM($H6)&" | "&TRIM($I6))) -> working | | | L6: =IF($B6="","",SUMPRODUCT(--ISNUMBER(SEARCH(SensorKW,$K6)))>0) -> FALSE | M6: =IF($B6="","",SUMPRODUCT(--ISNUMBER(SEARCH(DisplayKW,$K6)))>0) -> FALSE | N6: =IF($B6="","",SUMPRODUCT(--ISNUMBER(SEARCH(KeypadKW,$K6)))>0) -> FALSE | O6: =IF($B6="","",SUMPRODUCT(--ISNUMBER(SEARCH(PowerKW,$K6)))>0) -> FALSE | P6: =IF($B6="","",SUMPRODUCT(--ISNUMBER(SEARCH(SpeakerKW,$K6)))>0) -> FALSE | Q6: =IF($B6="","",OR(SUMPRODUCT(--ISNUMBER(SEARCH(EmptyKW,$K6)))>0,LOWER(TRIM($F6))="empty")) -> FALSE | R6: =IF($B6="","",OR(ISNUMBER(SEARCH("repair",$G6)),ISNUMBER(SEARCH("not working",$G6)))) -> FALSE | S6: =IF(AND($B6<>"",$M6=TRUE(),$L6=FALSE(),$Q6=FALSE()),COUNTIFS($M$3:$M6,TRUE(),$L$3:$L6,FALSE(),$Q$3:$Q6,FALSE()),"") | T6: =IF($B6="","",IF($Q6=TRUE(),"U1",IF($L6=TRUE(),"S1",IF($M6=TRUE(),"D"&MIN(4,INT(($S6-1)/DisplayCapacity)+1),IF($N6=TRUE(),"K1",IF($O6=TRUE(),"P1",IF($P6=TRUE(),"U1",IF($R6=TRUE(),"U1","W")))))))) -> W | U6: =IF($T6="","",$T6&"-"&COUNTIF($T$3:T6,$T6)) -> W-3 | V6: =IF($B6="","",_xlfn.TEXTJOIN(" | ",TRUE(),IF($Q6=TRUE(),"Empty box - no physical device, verify status",""),IF(AND($P6=TRUE(),$L6=FALSE(),$M6=FALSE(),$N6=FALSE(),$O6=FALSE(),$Q6=FALSE()),"Speaker fault only - needs manual box assignment",""),IF(AND($R6=TRUE(),$L6=FALSE(),$M6=FALSE(),$N6=FALSE(),$O6=FALSE(),$P6=FALSE(),$Q6=FALSE()),"No fault detail given - needs technician inspection",""),IF(AND(COUNTIF($F$3:$F$252,$F6)>1,LOWER(TRIM($F6))<>"empty"),"Duplicate Serial No - verify device identity",""),IF((--$L6+--$M6+--$N6+--$O6+--$P6)>1,"Multiple fault types detected - review full details before repair",""))) | W6: 0
A7: 5 | B7: 46239.501 | C7: X628 | D7: =IF($B7="","",IFERROR(VLOOKUP(TRIM($C7),ModelMap,2,FALSE()),TRIM($C7))) -> X628 | E7: Negambo- Thelwaththa | F7: CDQ9200760081 | G7: Working | J7: Colour | K7: =IF($B7="","",LOWER(TRIM($G7)&" | "&TRIM($H7)&" | "&TRIM($I7))) -> working | | | L7: =IF($B7="","",SUMPRODUCT(--ISNUMBER(SEARCH(SensorKW,$K7)))>0) -> FALSE | M7: =IF($B7="","",SUMPRODUCT(--ISNUMBER(SEARCH(DisplayKW,$K7)))>0) -> FALSE | N7: =IF($B7="","",SUMPRODUCT(--ISNUMBER(SEARCH(KeypadKW,$K7)))>0) -> FALSE | O7: =IF($B7="","",SUMPRODUCT(--ISNUMBER(SEARCH(PowerKW,$K7)))>0) -> FALSE | P7: =IF($B7="","",SUMPRODUCT(--ISNUMBER(SEARCH(SpeakerKW,$K7)))>0) -> FALSE | Q7: =IF($B7="","",OR(SUMPRODUCT(--ISNUMBER(SEARCH(EmptyKW,$K7)))>0,LOWER(TRIM($F7))="empty")) -> FALSE | R7: =IF($B7="","",OR(ISNUMBER(SEARCH("repair",$G7)),ISNUMBER(SEARCH("not working",$G7)))) -> FALSE | S7: =IF(AND($B7<>"",$M7=TRUE(),$L7=FALSE(),$Q7=FALSE()),COUNTIFS($M$3:$M7,TRUE(),$L$3:$L7,FALSE(),$Q$3:$Q7,FALSE()),"") | T7: =IF($B7="","",IF($Q7=TRUE(),"U1",IF($L7=TRUE(),"S1",IF($M7=TRUE(),"D"&MIN(4,INT(($S7-1)/DisplayCapacity)+1),IF($N7=TRUE(),"K1",IF($O7=TRUE(),"P1",IF($P7=TRUE(),"U1",IF($R7=TRUE(),"U1","W")))))))) -> W | U7: =IF($T7="","",$T7&"-"&COUNTIF($T$3:T7,$T7)) -> W-4 | V7: =IF($B7="","",_xlfn.TEXTJOIN(" | ",TRUE(),IF($Q7=TRUE(),"Empty box - no physical device, verify status",""),IF(AND($P7=TRUE(),$L7=FALSE(),$M7=FALSE(),$N7=FALSE(),$O7=FALSE(),$Q7=FALSE()),"Speaker fault only - needs manual box assignment",""),IF(AND($R7=TRUE(),$L7=FALSE(),$M7=FALSE(),$N7=FALSE(),$O7=FALSE(),$P7=FALSE(),$Q7=FALSE()),"No fault detail given - needs technician inspection",""),IF(AND(COUNTIF($F$3:$F$252,$F7)>1,LOWER(TRIM($F7))<>"empty"),"Duplicate Serial No - verify device identity",""),IF((--$L7+--$M7+--$N7+--$O7+--$P7)>1,"Multiple fault types detected - review full details before repair",""))) | W7: 0
A8: 6 | B8: 46239.508 | C8: X628 | D8: =IF($B8="","",IFERROR(VLOOKUP(TRIM($C8),ModelMap,2,FALSE()),TRIM($C8))) -> X628 | E8: Thihariya | F8: CDQ9193960102 | G8: Have to Repair | J8: Colour | K8: =IF($B8="","",LOWER(TRIM($G8)&" | "&TRIM($H8)&" | "&TRIM($I8))) -> have to repair | | | L8: =IF($B8="","",SUMPRODUCT(--ISNUMBER(SEARCH(SensorKW,$K8)))>0) -> FALSE | M8: =IF($B8="","",SUMPRODUCT(--ISNUMBER(SEARCH(DisplayKW,$K8)))>0) -> FALSE | N8: =IF($B8="","",SUMPRODUCT(--ISNUMBER(SEARCH(KeypadKW,$K8)))>0) -> FALSE | O8: =IF($B8="","",SUMPRODUCT(--ISNUMBER(SEARCH(PowerKW,$K8)))>0) -> FALSE | P8: =IF($B8="","",SUMPRODUCT(--ISNUMBER(SEARCH(SpeakerKW,$K8)))>0) -> FALSE | Q8: =IF($B8="","",OR(SUMPRODUCT(--ISNUMBER(SEARCH(EmptyKW,$K8)))>0,LOWER(TRIM($F8))="empty")) -> FALSE | R8: =IF($B8="","",OR(ISNUMBER(SEARCH("repair",$G8)),ISNUMBER(SEARCH("not working",$G8)))) -> TRUE | S8: =IF(AND($B8<>"",$M8=TRUE(),$L8=FALSE(),$Q8=FALSE()),COUNTIFS($M$3:$M8,TRUE(),$L$3:$L8,FALSE(),$Q$3:$Q8,FALSE()),"") | T8: =IF($B8="","",IF($Q8=TRUE(),"U1",IF($L8=TRUE(),"S1",IF($M8=TRUE(),"D"&MIN(4,INT(($S8-1)/DisplayCapacity)+1),IF($N8=TRUE(),"K1",IF($O8=TRUE(),"P1",IF($P8=TRUE(),"U1",IF($R8=TRUE(),"U1","W")))))))) -> U1 | U8: =IF($T8="","",$T8&"-"&COUNTIF($T$3:T8,$T8)) -> U1-1 | V8: =IF($B8="","",_xlfn.TEXTJOIN(" | ",TRUE(),IF($Q8=TRUE(),"Empty box - no physical device, verify status",""),IF(AND($P8=TRUE(),$L8=FALSE(),$M8=FALSE(),$N8=FALSE(),$O8=FALSE(),$Q8=FALSE()),"Speaker fault only - needs manual box assignment",""),IF(AND($R8=TRUE(),$L8=FALSE(),$M8=FALSE(),$N8=FALSE(),$O8=FALSE(),$P8=FALSE(),$Q8=FALSE()),"No fault detail given - needs technician inspection",""),IF(AND(COUNTIF($F$3:$F$252,$F8)>1,LOWER(TRIM($F8))<>"empty"),"Duplicate Serial No - verify device identity",""),IF((--$L8+--$M8+--$N8+--$O8+--$P8)>1,"Multiple fault types detected - review full details before repair",""))) -> No fault detail given - needs technician inspection | W8: 0
A9: 7 | B9: 46239.512 | C9: X628 | D9: =IF($B9="","",IFERROR(VLOOKUP(TRIM($C9),ModelMap,2,FALSE()),TRIM($C9))) -> X628 | E9: Kadawatha CC | F9: 0NQ9193960105 | G9: Have to Repair | H9: Display Error | J9: Colour | K9: =IF($B9="","",LOWER(TRIM($G9)&" | "&TRIM($H9)&" | "&TRIM($I9))) -> have to repair | display error | | L9: =IF($B9="","",SUMPRODUCT(--ISNUMBER(SEARCH(SensorKW,$K9)))>0) -> FALSE | M9: =IF($B9="","",SUMPRODUCT(--ISNUMBER(SEARCH(DisplayKW,$K9)))>0) -> TRUE | N9: =IF($B9="","",SUMPRODUCT(--ISNUMBER(SEARCH(KeypadKW,$K9)))>0) -> FALSE | O9: =IF($B9="","",SUMPRODUCT(--ISNUMBER(SEARCH(PowerKW,$K9)))>0) -> FALSE | P9: =IF($B9="","",SUMPRODUCT(--ISNUMBER(SEARCH(SpeakerKW,$K9)))>0) -> FALSE | Q9: =IF($B9="","",OR(SUMPRODUCT(--ISNUMBER(SEARCH(EmptyKW,$K9)))>0,LOWER(TRIM($F9))="empty")) -> FALSE | R9: =IF($B9="","",OR(ISNUMBER(SEARCH("repair",$G9)),ISNUMBER(SEARCH("not working",$G9)))) -> TRUE | S9: =IF(AND($B9<>"",$M9=TRUE(),$L9=FALSE(),$Q9=FALSE()),COUNTIFS($M$3:$M9,TRUE(),$L$3:$L9,FALSE(),$Q$3:$Q9,FALSE()),"") -> 1 | T9: =IF($B9="","",IF($Q9=TRUE(),"U1",IF($L9=TRUE(),"S1",IF($M9=TRUE(),"D"&MIN(4,INT(($S9-1)/DisplayCapacity)+1),IF($N9=TRUE(),"K1",IF($O9=TRUE(),"P1",IF($P9=TRUE(),"U1",IF($R9=TRUE(),"U1","W")))))))) -> D1 | U9: =IF($T9="","",$T9&"-"&COUNTIF($T$3:T9,$T9)) -> D1-1 | V9: =IF($B9="","",_xlfn.TEXTJOIN(" | ",TRUE(),IF($Q9=TRUE(),"Empty box - no physical device, verify status",""),IF(AND($P9=TRUE(),$L9=FALSE(),$M9=FALSE(),$N9=FALSE(),$O9=FALSE(),$Q9=FALSE()),"Speaker fault only - needs manual box assignment",""),IF(AND($R9=TRUE(),$L9=FALSE(),$M9=FALSE(),$N9=FALSE(),$O9=FALSE(),$P9=FALSE(),$Q9=FALSE()),"No fault detail given - needs technician inspection",""),IF(AND(COUNTIF($F$3:$F$252,$F9)>1,LOWER(TRIM($F9))<>"empty"),"Duplicate Serial No - verify device identity",""),IF((--$L9+--$M9+--$N9+--$O9+--$P9)>1,"Multiple fault types detected - review full details before repair",""))) | W9: 0
A10: 8 | B10: 46239.515 | C10: X628 | D10: =IF($B10="","",IFERROR(VLOOKUP(TRIM($C10),ModelMap,2,FALSE()),TRIM($C10))) -> X628 | E10: Negambo- Kurana | F10: CDQ9200760084 | G10: Working | J10: Colour | K10: =IF($B10="","",LOWER(TRIM($G10)&" | "&TRIM($H10)&" | "&TRIM($I10))) -> working | | | L10: =IF($B10="","",SUMPRODUCT(--ISNUMBER(SEARCH(SensorKW,$K10)))>0) -> FALSE | M10: =IF($B10="","",SUMPRODUCT(--ISNUMBER(SEARCH(DisplayKW,$K10)))>0) -> FALSE | N10: =IF($B10="","",SUMPRODUCT(--ISNUMBER(SEARCH(KeypadKW,$K10)))>0) -> FALSE | O10: =IF($B10="","",SUMPRODUCT(--ISNUMBER(SEARCH(PowerKW,$K10)))>0) -> FALSE | P10: =IF($B10="","",SUMPRODUCT(--ISNUMBER(SEARCH(SpeakerKW,$K10)))>0) -> FALSE | Q10: =IF($B10="","",OR(SUMPRODUCT(--ISNUMBER(SEARCH(EmptyKW,$K10)))>0,LOWER(TRIM($F10))="empty")) -> FALSE | R10: =IF($B10="","",OR(ISNUMBER(SEARCH("repair",$G10)),ISNUMBER(SEARCH("not working",$G10)))) -> FALSE | S10: =IF(AND($B10<>"",$M10=TRUE(),$L10=FALSE(),$Q10=FALSE()),COUNTIFS($M$3:$M10,TRUE(),$L$3:$L10,FALSE(),$Q$3:$Q10,FALSE()),"") | T10: =IF($B10="","",IF($Q10=TRUE(),"U1",IF($L10=TRUE(),"S1",IF($M10=TRUE(),"D"&MIN(4,INT(($S10-1)/DisplayCapacity)+1),IF($N10=TRUE(),"K1",IF($O10=TRUE(),"P1",IF($P10=TRUE(),"U1",IF($R10=TRUE(),"U1","W")))))))) -> W | U10: =IF($T10="","",$T10&"-"&COUNTIF($T$3:T10,$T10)) -> W-5 | V10: =IF($B10="","",_xlfn.TEXTJOIN(" | ",TRUE(),IF($Q10=TRUE(),"Empty box - no physical device, verify status",""),IF(AND($P10=TRUE(),$L10=FALSE(),$M10=FALSE(),$N10=FALSE(),$O10=FALSE(),$Q10=FALSE()),"Speaker fault only - needs manual box assignment",""),IF(AND($R10=TRUE(),$L10=FALSE(),$M10=FALSE(),$N10=FALSE(),$O10=FALSE(),$P10=FALSE(),$Q10=FALSE()),"No fault detail given - needs technician inspection",""),IF(AND(COUNTIF($F$3:$F$252,$F10)>1,LOWER(TRIM($F10))<>"empty"),"Duplicate Serial No - verify device identity",""),IF((--$L10+--$M10+--$N10+--$O10+--$P10)>1,"Multiple fault types detected - review full details before repair",""))) | W10: 0
A11: 9 | B11: 46239.519 | C11: X628 | D11: =IF($B11="","",IFERROR(VLOOKUP(TRIM($C11),ModelMap,2,FALSE()),TRIM($C11))) -> X628 | E11: Negambo 02 | F11: CDQ9184760006 | G11: Working, Have to Repair | I11: Keypad have to repair | J11: Colour | K11: =IF($B11="","",LOWER(TRIM($G11)&" | "&TRIM($H11)&" | "&TRIM($I11))) -> working, have to repair | | keypad have to repair | L11: =IF($B11="","",SUMPRODUCT(--ISNUMBER(SEARCH(SensorKW,$K11)))>0) -> FALSE | M11: =IF($B11="","",SUMPRODUCT(--ISNUMBER(SEARCH(DisplayKW,$K11)))>0) -> FALSE | N11: =IF($B11="","",SUMPRODUCT(--ISNUMBER(SEARCH(KeypadKW,$K11)))>0) -> TRUE | O11: =IF($B11="","",SUMPRODUCT(--ISNUMBER(SEARCH(PowerKW,$K11)))>0) -> FALSE | P11: =IF($B11="","",SUMPRODUCT(--ISNUMBER(SEARCH(SpeakerKW,$K11)))>0) -> FALSE | Q11: =IF($B11="","",OR(SUMPRODUCT(--ISNUMBER(SEARCH(EmptyKW,$K11)))>0,LOWER(TRIM($F11))="empty")) -> FALSE | R11: =IF($B11="","",OR(ISNUMBER(SEARCH("repair",$G11)),ISNUMBER(SEARCH("not working",$G11)))) -> TRUE | S11: =IF(AND($B11<>"",$M11=TRUE(),$L11=FALSE(),$Q11=FALSE()),COUNTIFS($M$3:$M11,TRUE(),$L$3:$L11,FALSE(),$Q$3:$Q11,FALSE()),"") | T11: =IF($B11="","",IF($Q11=TRUE(),"U1",IF($L11=TRUE(),"S1",IF($M11=TRUE(),"D"&MIN(4,INT(($S11-1)/DisplayCapacity)+1),IF($N11=TRUE(),"K1",IF($O11=TRUE(),"P1",IF($P11=TRUE(),"U1",IF($R11=TRUE(),"U1","W")))))))) -> K1 | U11: =IF($T11="","",$T11&"-"&COUNTIF($T$3:T11,$T11)) -> K1-1 | V11: =IF($B11="","",_xlfn.TEXTJOIN(" | ",TRUE(),IF($Q11=TRUE(),"Empty box - no physical device, verify status",""),IF(AND($P11=TRUE(),$L11=FALSE(),$M11=FALSE(),$N11=FALSE(),$O11=FALSE(),$Q11=FALSE()),"Speaker fault only - needs manual box assignment",""),IF(AND($R11=TRUE(),$L11=FALSE(),$M11=FALSE(),$N11=FALSE(),$O11=FALSE(),$P11=FALSE(),$Q11=FALSE()),"No fault detail given - needs technician inspection",""),IF(AND(COUNTIF($F$3:$F$252,$F11)>1,LOWER(TRIM($F11))<>"empty"),"Duplicate Serial No - verify device identity",""),IF((--$L11+--$M11+--$N11+--$O11+--$P11)>1,"Multiple fault types detected - review full details before repair",""))) | W11: 0
A12: 10 | B12: 46239.522 | C12: TX628 | D12: =IF($B12="","",IFERROR(VLOOKUP(TRIM($C12),ModelMap,2,FALSE()),TRIM($C12))) -> TX628 | E12: Kirillawela | F12: 6160062164907 | G12: Working | J12: Colour | K12: =IF($B12="","",LOWER(TRIM($G12)&" | "&TRIM($H12)&" | "&TRIM($I12))) -> working | | | L12: =IF($B12="","",SUMPRODUCT(--ISNUMBER(SEARCH(SensorKW,$K12)))>0) -> FALSE | M12: =IF($B12="","",SUMPRODUCT(--ISNUMBER(SEARCH(DisplayKW,$K12)))>0) -> FALSE | N12: =IF($B12="","",SUMPRODUCT(--ISNUMBER(SEARCH(KeypadKW,$K12)))>0) -> FALSE | O12: =IF($B12="","",SUMPRODUCT(--ISNUMBER(SEARCH(PowerKW,$K12)))>0) -> FALSE | P12: =IF($B12="","",SUMPRODUCT(--ISNUMBER(SEARCH(SpeakerKW,$K12)))>0) -> FALSE | Q12: =IF($B12="","",OR(SUMPRODUCT(--ISNUMBER(SEARCH(EmptyKW,$K12)))>0,LOWER(TRIM($F12))="empty")) -> FALSE | R12: =IF($B12="","",OR(ISNUMBER(SEARCH("repair",$G12)),ISNUMBER(SEARCH("not working",$G12)))) -> FALSE | S12: =IF(AND($B12<>"",$M12=TRUE(),$L12=FALSE(),$Q12=FALSE()),COUNTIFS($M$3:$M12,TRUE(),$L$3:$L12,FALSE(),$Q$3:$Q12,FALSE()),"") | T12: =IF($B12="","",IF($Q12=TRUE(),"U1",IF($L12=TRUE(),"S1",IF($M12=TRUE(),"D"&MIN(4,INT(($S12-1)/DisplayCapacity)+1),IF($N12=TRUE(),"K1",IF($O12=TRUE(),"P1",IF($P12=TRUE(),"U1",IF($R12=TRUE(),"U1","W")))))))) -> W | U12: =IF($T12="","",$T12&"-"&COUNTIF($T$3:T12,$T12)) -> W-6 | V12: =IF($B12="","",_xlfn.TEXTJOIN(" | ",TRUE(),IF($Q12=TRUE(),"Empty box - no physical device, verify status",""),IF(AND($P12=TRUE(),$L12=FALSE(),$M12=FALSE(),$N12=FALSE(),$O12=FALSE(),$Q12=FALSE()),"Speaker fault only - needs manual box assignment",""),IF(AND($R12=TRUE(),$L12=FALSE(),$M12=FALSE(),$N12=FALSE(),$O12=FALSE(),$P12=FALSE(),$Q12=FALSE()),"No fault detail given - needs technician inspection",""),IF(AND(COUNTIF($F$3:$F$252,$F12)>1,LOWER(TRIM($F12))<>"empty"),"Duplicate Serial No - verify device identity",""),IF((--$L12+--$M12+--$N12+--$O12+--$P12)>1,"Multiple fault types detected - review full details before repair",""))) | W12: 0
A13: 11 | B13: 46239.537 | C13: X628 | D13: =IF($B13="","",IFERROR(VLOOKUP(TRIM($C13),ModelMap,2,FALSE()),TRIM($C13))) -> X628 | E13: Chillaw | F13: 5128193500007 | G13: Working, Have to Repair | H13: No sensor and also have power issue some time device is off automatically | J13: Colour | K13: =IF($B13="","",LOWER(TRIM($G13)&" | "&TRIM($H13)&" | "&TRIM($I13))) -> working, have to repair | no sensor and also have power issue some time device is off automatically | | L13: =IF($B13="","",SUMPRODUCT(--ISNUMBER(SEARCH(SensorKW,$K13)))>0) -> TRUE | M13: =IF($B13="","",SUMPRODUCT(--ISNUMBER(SEARCH(DisplayKW,$K13)))>0) -> FALSE | N13: =IF($B13="","",SUMPRODUCT(--ISNUMBER(SEARCH(KeypadKW,$K13)))>0) -> FALSE | O13: =IF($B13="","",SUMPRODUCT(--ISNUMBER(SEARCH(PowerKW,$K13)))>0) -> TRUE | P13: =IF($B13="","",SUMPRODUCT(--ISNUMBER(SEARCH(SpeakerKW,$K13)))>0) -> FALSE | Q13: =IF($B13="","",OR(SUMPRODUCT(--ISNUMBER(SEARCH(EmptyKW,$K13)))>0,LOWER(TRIM($F13))="empty")) -> FALSE | R13: =IF($B13="","",OR(ISNUMBER(SEARCH("repair",$G13)),ISNUMBER(SEARCH("not working",$G13)))) -> TRUE | S13: =IF(AND($B13<>"",$M13=TRUE(),$L13=FALSE(),$Q13=FALSE()),COUNTIFS($M$3:$M13,TRUE(),$L$3:$L13,FALSE(),$Q$3:$Q13,FALSE()),"") | T13: =IF($B13="","",IF($Q13=TRUE(),"U1",IF($L13=TRUE(),"S1",IF($M13=TRUE(),"D"&MIN(4,INT(($S13-1)/DisplayCapacity)+1),IF($N13=TRUE(),"K1",IF($O13=TRUE(),"P1",IF($P13=TRUE(),"U1",IF($R13=TRUE(),"U1","W")))))))) -> S1 | U13: =IF($T13="","",$T13&"-"&COUNTIF($T$3:T13,$T13)) -> S1-1 | V13: =IF($B13="","",_xlfn.TEXTJOIN(" | ",TRUE(),IF($Q13=TRUE(),"Empty box - no physical device, verify status",""),IF(AND($P13=TRUE(),$L13=FALSE(),$M13=FALSE(),$N13=FALSE(),$O13=FALSE(),$Q13=FALSE()),"Speaker fault only - needs manual box assignment",""),IF(AND($R13=TRUE(),$L13=FALSE(),$M13=FALSE(),$N13=FALSE(),$O13=FALSE(),$P13=FALSE(),$Q13=FALSE()),"No fault detail given - needs technician inspection",""),IF(AND(COUNTIF($F$3:$F$252,$F13)>1,LOWER(TRIM($F13))<>"empty"),"Duplicate Serial No - verify device identity",""),IF((--$L13+--$M13+--$N13+--$O13+--$P13)>1,"Multiple fault types detected - review full details before repair",""))) -> Multiple fault types detected - review full details before repair | W13: 0
A14: 12 | B14: 46239.543 | C14: X628 | D14: =IF($B14="","",IFERROR(VLOOKUP(TRIM($C14),ModelMap,2,FALSE()),TRIM($C14))) -> X628 | E14: Gampaha | F14: A5RN174660002 | G14: Working | J14: Black & White | K14: =IF($B14="","",LOWER(TRIM($G14)&" | "&TRIM($H14)&" | "&TRIM($I14))) -> working | | | L14: =IF($B14="","",SUMPRODUCT(--ISNUMBER(SEARCH(SensorKW,$K14)))>0) -> FALSE | M14: =IF($B14="","",SUMPRODUCT(--ISNUMBER(SEARCH(DisplayKW,$K14)))>0) -> FALSE | N14: =IF($B14="","",SUMPRODUCT(--ISNUMBER(SEARCH(KeypadKW,$K14)))>0) -> FALSE | O14: =IF($B14="","",SUMPRODUCT(--ISNUMBER(SEARCH(PowerKW,$K14)))>0) -> FALSE | P14: =IF($B14="","",SUMPRODUCT(--ISNUMBER(SEARCH(SpeakerKW,$K14)))>0) -> FALSE | Q14: =IF($B14="","",OR(SUMPRODUCT(--ISNUMBER(SEARCH(EmptyKW,$K14)))>0,LOWER(TRIM($F14))="empty")) -> FALSE | R14: =IF($B14="","",OR(ISNUMBER(SEARCH("repair",$G14)),ISNUMBER(SEARCH("not working",$G14)))) -> FALSE | S14: =IF(AND($B14<>"",$M14=TRUE(),$L14=FALSE(),$Q14=FALSE()),COUNTIFS($M$3:$M14,TRUE(),$L$3:$L14,FALSE(),$Q$3:$Q14,FALSE()),"") | T14: =IF($B14="","",IF($Q14=TRUE(),"U1",IF($L14=TRUE(),"S1",IF($M14=TRUE(),"D"&MIN(4,INT(($S14-1)/DisplayCapacity)+1),IF($N14=TRUE(),"K1",IF($O14=TRUE(),"P1",IF($P14=TRUE(),"U1",IF($R14=TRUE(),"U1","W")))))))) -> W | U14: =IF($T14="","",$T14&"-"&COUNTIF($T$3:T14,$T14)) -> W-7 | V14: =IF($B14="","",_xlfn.TEXTJOIN(" | ",TRUE(),IF($Q14=TRUE(),"Empty box - no physical device, verify status",""),IF(AND($P14=TRUE(),$L14=FALSE(),$M14=FALSE(),$N14=FALSE(),$O14=FALSE(),$Q14=FALSE()),"Speaker fault only - needs manual box assignment",""),IF(AND($R14=TRUE(),$L14=FALSE(),$M14=FALSE(),$N14=FALSE(),$O14=FALSE(),$P14=FALSE(),$Q14=FALSE()),"No fault detail given - needs technician inspection",""),IF(AND(COUNTIF($F$3:$F$252,$F14)>1,LOWER(TRIM($F14))<>"empty"),"Duplicate Serial No - verify device identity",""),IF((--$L14+--$M14+--$N14+--$O14+--$P14)>1,"Multiple fault types detected - review full details before repair",""))) | W14: 0
A15: 13 | B15: 46239.548 | C15: X628 | D15: =IF($B15="","",IFERROR(VLOOKUP(TRIM($C15),ModelMap,2,FALSE()),TRIM($C15))) -> X628 | E15: Minuwangoda | F15: A5SA182160001 | G15: Working | I15: Have to repair keypad | J15: Black & White | K15: =IF($B15="","",LOWER(TRIM($G15)&" | "&TRIM($H15)&" | "&TRIM($I15))) -> working | | have to repair keypad | L15: =IF($B15="","",SUMPRODUCT(--ISNUMBER(SEARCH(SensorKW,$K15)))>0) -> FALSE | M15: =IF($B15="","",SUMPRODUCT(--ISNUMBER(SEARCH(DisplayKW,$K15)))>0) -> FALSE | N15: =IF($B15="","",SUMPRODUCT(--ISNUMBER(SEARCH(KeypadKW,$K15)))>0) -> TRUE | O15: =IF($B15="","",SUMPRODUCT(--ISNUMBER(SEARCH(PowerKW,$K15)))>0) -> FALSE | P15: =IF($B15="","",SUMPRODUCT(--ISNUMBER(SEARCH(SpeakerKW,$K15)))>0) -> FALSE | Q15: =IF($B15="","",OR(SUMPRODUCT(--ISNUMBER(SEARCH(EmptyKW,$K15)))>0,LOWER(TRIM($F15))="empty")) -> FALSE | R15: =IF($B15="","",OR(ISNUMBER(SEARCH("repair",$G15)),ISNUMBER(SEARCH("not working",$G15)))) -> FALSE | S15: =IF(AND($B15<>"",$M15=TRUE(),$L15=FALSE(),$Q15=FALSE()),COUNTIFS($M$3:$M15,TRUE(),$L$3:$L15,FALSE(),$Q$3:$Q15,FALSE()),"") | T15: =IF($B15="","",IF($Q15=TRUE(),"U1",IF($L15=TRUE(),"S1",IF($M15=TRUE(),"D"&MIN(4,INT(($S15-1)/DisplayCapacity)+1),IF($N15=TRUE(),"K1",IF($O15=TRUE(),"P1",IF($P15=TRUE(),"U1",IF($R15=TRUE(),"U1","W")))))))) -> K1 | U15: =IF($T15="","",$T15&"-"&COUNTIF($T$3:T15,$T15)) -> K1-2 | V15: =IF($B15="","",_xlfn.TEXTJOIN(" | ",TRUE(),IF($Q15=TRUE(),"Empty box - no physical device, verify status",""),IF(AND($P15=TRUE(),$L15=FALSE(),$M15=FALSE(),$N15=FALSE(),$O15=FALSE(),$Q15=FALSE()),"Speaker fault only - needs manual box assignment",""),IF(AND($R15=TRUE(),$L15=FALSE(),$M15=FALSE(),$N15=FALSE(),$O15=FALSE(),$P15=FALSE(),$Q15=FALSE()),"No fault detail given - needs technician inspection",""),IF(AND(COUNTIF($F$3:$F$252,$F15)>1,LOWER(TRIM($F15))<>"empty"),"Duplicate Serial No - verify device identity",""),IF((--$L15+--$M15+--$N15+--$O15+--$P15)>1,"Multiple fault types detected - review full details before repair",""))) | W15: 0
A16: 14 | B16: 46239.554 | C16: X628 | D16: =IF($B16="","",IFERROR(VLOOKUP(TRIM($C16),ModelMap,2,FALSE()),TRIM($C16))) -> X628 | E16: Andiambalama | F16: 0065653040014 | G16: Working | I16: Display is not clear | J16: Black & White | K16: =IF($B16="","",LOWER(TRIM($G16)&" | "&TRIM($H16)&" | "&TRIM($I16))) -> working | | display is not clear | L16: =IF($B16="","",SUMPRODUCT(--ISNUMBER(SEARCH(SensorKW,$K16)))>0) -> FALSE | M16: =IF($B16="","",SUMPRODUCT(--ISNUMBER(SEARCH(DisplayKW,$K16)))>0) -> TRUE | N16: =IF($B16="","",SUMPRODUCT(--ISNUMBER(SEARCH(KeypadKW,$K16)))>0) -> FALSE | O16: =IF($B16="","",SUMPRODUCT(--ISNUMBER(SEARCH(PowerKW,$K16)))>0) -> FALSE | P16: =IF($B16="","",SUMPRODUCT(--ISNUMBER(SEARCH(SpeakerKW,$K16)))>0) -> FALSE | Q16: =IF($B16="","",OR(SUMPRODUCT(--ISNUMBER(SEARCH(EmptyKW,$K16)))>0,LOWER(TRIM($F16))="empty")) -> FALSE | R16: =IF($B16="","",OR(ISNUMBER(SEARCH("repair",$G16)),ISNUMBER(SEARCH("not working",$G16)))) -> FALSE | S16: =IF(AND($B16<>"",$M16=TRUE(),$L16=FALSE(),$Q16=FALSE()),COUNTIFS($M$3:$M16,TRUE(),$L$3:$L16,FALSE(),$Q$3:$Q16,FALSE()),"") -> 2 | T16: =IF($B16="","",IF($Q16=TRUE(),"U1",IF($L16=TRUE(),"S1",IF($M16=TRUE(),"D"&MIN(4,INT(($S16-1)/DisplayCapacity)+1),IF($N16=TRUE(),"K1",IF($O16=TRUE(),"P1",IF($P16=TRUE(),"U1",IF($R16=TRUE(),"U1","W")))))))) -> D1 | U16: =IF($T16="","",$T16&"-"&COUNTIF($T$3:T16,$T16)) -> D1-2 | V16: =IF($B16="","",_xlfn.TEXTJOIN(" | ",TRUE(),IF($Q16=TRUE(),"Empty box - no physical device, verify status",""),IF(AND($P16=TRUE(),$L16=FALSE(),$M16=FALSE(),$N16=FALSE(),$O16=FALSE(),$Q16=FALSE()),"Speaker fault only - needs manual box assignment",""),IF(AND($R16=TRUE(),$L16=FALSE(),$M16=FALSE(),$N16=FALSE(),$O16=FALSE(),$P16=FALSE(),$Q16=FALSE()),"No fault detail given - needs technician inspection",""),IF(AND(COUNTIF($F$3:$F$252,$F16)>1,LOWER(TRIM($F16))<>"empty"),"Duplicate Serial No - verify device identity",""),IF((--$L16+--$M16+--$N16+--$O16+--$P16)>1,"Multiple fault types detected - review full details before repair",""))) | W16: 0
A17: 15 | B17: 46239.559 | C17: X628 | D17: =IF($B17="","",IFERROR(VLOOKUP(TRIM($C17),ModelMap,2,FALSE()),TRIM($C17))) -> X628 | E17: Ganemulla | F17: AEG8243600005 | G17: Working | J17: Colour | K17: =IF($B17="","",LOWER(TRIM($G17)&" | "&TRIM($H17)&" | "&TRIM($I17))) -> working | | | L17: =IF($B17="","",SUMPRODUCT(--ISNUMBER(SEARCH(SensorKW,$K17)))>0) -> FALSE | M17: =IF($B17="","",SUMPRODUCT(--ISNUMBER(SEARCH(DisplayKW,$K17)))>0) -> FALSE | N17: =IF($B17="","",SUMPRODUCT(--ISNUMBER(SEARCH(KeypadKW,$K17)))>0) -> FALSE | O17: =IF($B17="","",SUMPRODUCT(--ISNUMBER(SEARCH(PowerKW,$K17)))>0) -> FALSE | P17: =IF($B17="","",SUMPRODUCT(--ISNUMBER(SEARCH(SpeakerKW,$K17)))>0) -> FALSE | Q17: =IF($B17="","",OR(SUMPRODUCT(--ISNUMBER(SEARCH(EmptyKW,$K17)))>0,LOWER(TRIM($F17))="empty")) -> FALSE | R17: =IF($B17="","",OR(ISNUMBER(SEARCH("repair",$G17)),ISNUMBER(SEARCH("not working",$G17)))) -> FALSE | S17: =IF(AND($B17<>"",$M17=TRUE(),$L17=FALSE(),$Q17=FALSE()),COUNTIFS($M$3:$M17,TRUE(),$L$3:$L17,FALSE(),$Q$3:$Q17,FALSE()),"") | T17: =IF($B17="","",IF($Q17=TRUE(),"U1",IF($L17=TRUE(),"S1",IF($M17=TRUE(),"D"&MIN(4,INT(($S17-1)/DisplayCapacity)+1),IF($N17=TRUE(),"K1",IF($O17=TRUE(),"P1",IF($P17=TRUE(),"U1",IF($R17=TRUE(),"U1","W")))))))) -> W | U17: =IF($T17="","",$T17&"-"&COUNTIF($T$3:T17,$T17)) -> W-8 | V17: =IF($B17="","",_xlfn.TEXTJOIN(" | ",TRUE(),IF($Q17=TRUE(),"Empty box - no physical device, verify status",""),IF(AND($P17=TRUE(),$L17=FALSE(),$M17=FALSE(),$N17=FALSE(),$O17=FALSE(),$Q17=FALSE()),"Speaker fault only - needs manual box assignment",""),IF(AND($R17=TRUE(),$L17=FALSE(),$M17=FALSE(),$N17=FALSE(),$O17=FALSE(),$P17=FALSE(),$Q17=FALSE()),"No fault detail given - needs technician inspection",""),IF(AND(COUNTIF($F$3:$F$252,$F17)>1,LOWER(TRIM($F17))<>"empty"),"Duplicate Serial No - verify device identity",""),IF((--$L17+--$M17+--$N17+--$O17+--$P17)>1,"Multiple fault types detected - review full details before repair",""))) | W17: 0
A18: 16 | B18: 46239.565 | C18: TX628 | D18: =IF($B18="","",IFERROR(VLOOKUP(TRIM($C18),ModelMap,2,FALSE()),TRIM($C18))) -> TX628 | E18: Yakkala | F18: AEYW092380605 | G18: Working | J18: Colour | K18: =IF($B18="","",LOWER(TRIM($G18)&" | "&TRIM($H18)&" | "&TRIM($I18))) -> working | | | L18: =IF($B18="","",SUMPRODUCT(--ISNUMBER(SEARCH(SensorKW,$K18)))>0) -> FALSE | M18: =IF($B18="","",SUMPRODUCT(--ISNUMBER(SEARCH(DisplayKW,$K18)))>0) -> FALSE | N18: =IF($B18="","",SUMPRODUCT(--ISNUMBER(SEARCH(KeypadKW,$K18)))>0) -> FALSE | O18: =IF($B18="","",SUMPRODUCT(--ISNUMBER(SEARCH(PowerKW,$K18)))>0) -> FALSE | P18: =IF($B18="","",SUMPRODUCT(--ISNUMBER(SEARCH(SpeakerKW,$K18)))>0) -> FALSE | Q18: =IF($B18="","",OR(SUMPRODUCT(--ISNUMBER(SEARCH(EmptyKW,$K18)))>0,LOWER(TRIM($F18))="empty")) -> FALSE | R18: =IF($B18="","",OR(ISNUMBER(SEARCH("repair",$G18)),ISNUMBER(SEARCH("not working",$G18)))) -> FALSE | S18: =IF(AND($B18<>"",$M18=TRUE(),$L18=FALSE(),$Q18=FALSE()),COUNTIFS($M$3:$M18,TRUE(),$L$3:$L18,FALSE(),$Q$3:$Q18,FALSE()),"") | T18: =IF($B18="","",IF($Q18=TRUE(),"U1",IF($L18=TRUE(),"S1",IF($M18=TRUE(),"D"&MIN(4,INT(($S18-1)/DisplayCapacity)+1),IF($N18=TRUE(),"K1",IF($O18=TRUE(),"P1",IF($P18=TRUE(),"U1",IF($R18=TRUE(),"U1","W")))))))) -> W | U18: =IF($T18="","",$T18&"-"&COUNTIF($T$3:T18,$T18)) -> W-9 | V18: =IF($B18="","",_xlfn.TEXTJOIN(" | ",TRUE(),IF($Q18=TRUE(),"Empty box - no physical device, verify status",""),IF(AND($P18=TRUE(),$L18=FALSE(),$M18=FALSE(),$N18=FALSE(),$O18=FALSE(),$Q18=FALSE()),"Speaker fault only - needs manual box assignment",""),IF(AND($R18=TRUE(),$L18=FALSE(),$M18=FALSE(),$N18=FALSE(),$O18=FALSE(),$P18=FALSE(),$Q18=FALSE()),"No fault detail given - needs technician inspection",""),IF(AND(COUNTIF($F$3:$F$252,$F18)>1,LOWER(TRIM($F18))<>"empty"),"Duplicate Serial No - verify device identity",""),IF((--$L18+--$M18+--$N18+--$O18+--$P18)>1,"Multiple fault types detected - review full details before repair",""))) | W18: 0
A19: 17 | B19: 46239.571 | C19: X628 | D19: =IF($B19="","",IFERROR(VLOOKUP(TRIM($C19),ModelMap,2,FALSE()),TRIM($C19))) -> X628 | E19: Miriswaththa | F19: CDQ9192160004 | G19: Working | J19: Colour | K19: =IF($B19="","",LOWER(TRIM($G19)&" | "&TRIM($H19)&" | "&TRIM($I19))) -> working | | | L19: =IF($B19="","",SUMPRODUCT(--ISNUMBER(SEARCH(SensorKW,$K19)))>0) -> FALSE | M19: =IF($B19="","",SUMPRODUCT(--ISNUMBER(SEARCH(DisplayKW,$K19)))>0) -> FALSE | N19: =IF($B19="","",SUMPRODUCT(--ISNUMBER(SEARCH(KeypadKW,$K19)))>0) -> FALSE | O19: =IF($B19="","",SUMPRODUCT(--ISNUMBER(SEARCH(PowerKW,$K19)))>0) -> FALSE | P19: =IF($B19="","",SUMPRODUCT(--ISNUMBER(SEARCH(SpeakerKW,$K19)))>0) -> FALSE | Q19: =IF($B19="","",OR(SUMPRODUCT(--ISNUMBER(SEARCH(EmptyKW,$K19)))>0,LOWER(TRIM($F19))="empty")) -> FALSE | R19: =IF($B19="","",OR(ISNUMBER(SEARCH("repair",$G19)),ISNUMBER(SEARCH("not working",$G19)))) -> FALSE | S19: =IF(AND($B19<>"",$M19=TRUE(),$L19=FALSE(),$Q19=FALSE()),COUNTIFS($M$3:$M19,TRUE(),$L$3:$L19,FALSE(),$Q$3:$Q19,FALSE()),"") | T19: =IF($B19="","",IF($Q19=TRUE(),"U1",IF($L19=TRUE(),"S1",IF($M19=TRUE(),"D"&MIN(4,INT(($S19-1)/DisplayCapacity)+1),IF($N19=TRUE(),"K1",IF($O19=TRUE(),"P1",IF($P19=TRUE(),"U1",IF($R19=TRUE(),"U1","W")))))))) -> W | U19: =IF($T19="","",$T19&"-"&COUNTIF($T$3:T19,$T19)) -> W-10 | V19: =IF($B19="","",_xlfn.TEXTJOIN(" | ",TRUE(),IF($Q19=TRUE(),"Empty box - no physical device, verify status",""),IF(AND($P19=TRUE(),$L19=FALSE(),$M19=FALSE(),$N19=FALSE(),$O19=FALSE(),$Q19=FALSE()),"Speaker fault only - needs manual box assignment",""),IF(AND($R19=TRUE(),$L19=FALSE(),$M19=FALSE(),$N19=FALSE(),$O19=FALSE(),$P19=FALSE(),$Q19=FALSE()),"No fault detail given - needs technician inspection",""),IF(AND(COUNTIF($F$3:$F$252,$F19)>1,LOWER(TRIM($F19))<>"empty"),"Duplicate Serial No - verify device identity",""),IF((--$L19+--$M19+--$N19+--$O19+--$P19)>1,"Multiple fault types detected - review full details before repair",""))) | W19: 0
A20: 18 | B20: 46239.656 | C20: X628 | D20: =IF($B20="","",IFERROR(VLOOKUP(TRIM($C20),ModelMap,2,FALSE()),TRIM($C20))) -> X628 | E20: Thalawathugoda | F20: 6006183600002 | G20: Working | I20: Display is not clear | J20: Black & White | K20: =IF($B20="","",LOWER(TRIM($G20)&" | "&TRIM($H20)&" | "&TRIM($I20))) -> working | | display is not clear | L20: =IF($B20="","",SUMPRODUCT(--ISNUMBER(SEARCH(SensorKW,$K20)))>0) -> FALSE | M20: =IF($B20="","",SUMPRODUCT(--ISNUMBER(SEARCH(DisplayKW,$K20)))>0) -> TRUE | N20: =IF($B20="","",SUMPRODUCT(--ISNUMBER(SEARCH(KeypadKW,$K20)))>0) -> FALSE | O20: =IF($B20="","",SUMPRODUCT(--ISNUMBER(SEARCH(PowerKW,$K20)))>0) -> FALSE | P20: =IF($B20="","",SUMPRODUCT(--ISNUMBER(SEARCH(SpeakerKW,$K20)))>0) -> FALSE | Q20: =IF($B20="","",OR(SUMPRODUCT(--ISNUMBER(SEARCH(EmptyKW,$K20)))>0,LOWER(TRIM($F20))="empty")) -> FALSE | R20: =IF($B20="","",OR(ISNUMBER(SEARCH("repair",$G20)),ISNUMBER(SEARCH("not working",$G20)))) -> FALSE | S20: =IF(AND($B20<>"",$M20=TRUE(),$L20=FALSE(),$Q20=FALSE()),COUNTIFS($M$3:$M20,TRUE(),$L$3:$L20,FALSE(),$Q$3:$Q20,FALSE()),"") -> 3 | T20: =IF($B20="","",IF($Q20=TRUE(),"U1",IF($L20=TRUE(),"S1",IF($M20=TRUE(),"D"&MIN(4,INT(($S20-1)/DisplayCapacity)+1),IF($N20=TRUE(),"K1",IF($O20=TRUE(),"P1",IF($P20=TRUE(),"U1",IF($R20=TRUE(),"U1","W")))))))) -> D1 | U20: =IF($T20="","",$T20&"-"&COUNTIF($T$3:T20,$T20)) -> D1-3 | V20: =IF($B20="","",_xlfn.TEXTJOIN(" | ",TRUE(),IF($Q20=TRUE(),"Empty box - no physical device, verify status",""),IF(AND($P20=TRUE(),$L20=FALSE(),$M20=FALSE(),$N20=FALSE(),$O20=FALSE(),$Q20=FALSE()),"Speaker fault only - needs manual box assignment",""),IF(AND($R20=TRUE(),$L20=FALSE(),$M20=FALSE(),$N20=FALSE(),$O20=FALSE(),$P20=FALSE(),$Q20=FALSE()),"No fault detail given - needs technician inspection",""),IF(AND(COUNTIF($F$3:$F$252,$F20)>1,LOWER(TRIM($F20))<>"empty"),"Duplicate Serial No - verify device identity",""),IF((--$L20+--$M20+--$N20+--$O20+--$P20)>1,"Multiple fault types detected - review full details before repair",""))) | W20: 0
A21: 19 | B21: 46239.66 | C21: Iclock3000 | D21: =IF($B21="","",IFERROR(VLOOKUP(TRIM($C21),ModelMap,2,FALSE()),TRIM($C21))) -> iClock3000 | E21: Gothatuwa | F21: A7PT18036001 | G21: No Power Supply | K21: =IF($B21="","",LOWER(TRIM($G21)&" | "&TRIM($H21)&" | "&TRIM($I21))) -> no power supply | | | L21: =IF($B21="","",SUMPRODUCT(--ISNUMBER(SEARCH(SensorKW,$K21)))>0) -> FALSE | M21: =IF($B21="","",SUMPRODUCT(--ISNUMBER(SEARCH(DisplayKW,$K21)))>0) -> FALSE | N21: =IF($B21="","",SUMPRODUCT(--ISNUMBER(SEARCH(KeypadKW,$K21)))>0) -> FALSE | O21: =IF($B21="","",SUMPRODUCT(--ISNUMBER(SEARCH(PowerKW,$K21)))>0) -> TRUE | P21: =IF($B21="","",SUMPRODUCT(--ISNUMBER(SEARCH(SpeakerKW,$K21)))>0) -> FALSE | Q21: =IF($B21="","",OR(SUMPRODUCT(--ISNUMBER(SEARCH(EmptyKW,$K21)))>0,LOWER(TRIM($F21))="empty")) -> FALSE | R21: =IF($B21="","",OR(ISNUMBER(SEARCH("repair",$G21)),ISNUMBER(SEARCH("not working",$G21)))) -> FALSE | S21: =IF(AND($B21<>"",$M21=TRUE(),$L21=FALSE(),$Q21=FALSE()),COUNTIFS($M$3:$M21,TRUE(),$L$3:$L21,FALSE(),$Q$3:$Q21,FALSE()),"") | T21: =IF($B21="","",IF($Q21=TRUE(),"U1",IF($L21=TRUE(),"S1",IF($M21=TRUE(),"D"&MIN(4,INT(($S21-1)/DisplayCapacity)+1),IF($N21=TRUE(),"K1",IF($O21=TRUE(),"P1",IF($P21=TRUE(),"U1",IF($R21=TRUE(),"U1","W")))))))) -> P1 | U21: =IF($T21="","",$T21&"-"&COUNTIF($T$3:T21,$T21)) -> P1-2 | V21: =IF($B21="","",_xlfn.TEXTJOIN(" | ",TRUE(),IF($Q21=TRUE(),"Empty box - no physical device, verify status",""),IF(AND($P21=TRUE(),$L21=FALSE(),$M21=FALSE(),$N21=FALSE(),$O21=FALSE(),$Q21=FALSE()),"Speaker fault only - needs manual box assignment",""),IF(AND($R21=TRUE(),$L21=FALSE(),$M21=FALSE(),$N21=FALSE(),$O21=FALSE(),$P21=FALSE(),$Q21=FALSE()),"No fault detail given - needs technician inspection",""),IF(AND(COUNTIF($F$3:$F$252,$F21)>1,LOWER(TRIM($F21))<>"empty"),"Duplicate Serial No - verify device identity",""),IF((--$L21+--$M21+--$N21+--$O21+--$P21)>1,"Multiple fault types detected - review full details before repair",""))) | W21: 0
A22: 20 | B22: 46240.492 | C22: X-628 | D22: =IF($B22="","",IFERROR(VLOOKUP(TRIM($C22),ModelMap,2,FALSE()),TRIM($C22))) -> X628 | E22: Rathmalana | F22: 6006154200001 | G22: Working, Have to Repair | H22: Display have to replace and sensor board have issue some time | J22: Black & White | K22: =IF($B22="","",LOWER(TRIM($G22)&" | "&TRIM($H22)&" | "&TRIM($I22))) -> working, have to repair | display have to replace and sensor board have issue some time | | L22: =IF($B22="","",SUMPRODUCT(--ISNUMBER(SEARCH(SensorKW,$K22)))>0) -> TRUE | M22: =IF($B22="","",SUMPRODUCT(--ISNUMBER(SEARCH(DisplayKW,$K22)))>0) -> TRUE | N22: =IF($B22="","",SUMPRODUCT(--ISNUMBER(SEARCH(KeypadKW,$K22)))>0) -> FALSE | O22: =IF($B22="","",SUMPRODUCT(--ISNUMBER(SEARCH(PowerKW,$K22)))>0) -> FALSE | P22: =IF($B22="","",SUMPRODUCT(--ISNUMBER(SEARCH(SpeakerKW,$K22)))>0) -> FALSE | Q22: =IF($B22="","",OR(SUMPRODUCT(--ISNUMBER(SEARCH(EmptyKW,$K22)))>0,LOWER(TRIM($F22))="empty")) -> FALSE | R22: =IF($B22="","",OR(ISNUMBER(SEARCH("repair",$G22)),ISNUMBER(SEARCH("not working",$G22)))) -> TRUE | S22: =IF(AND($B22<>"",$M22=TRUE(),$L22=FALSE(),$Q22=FALSE()),COUNTIFS($M$3:$M22,TRUE(),$L$3:$L22,FALSE(),$Q$3:$Q22,FALSE()),"") | T22: =IF($B22="","",IF($Q22=TRUE(),"U1",IF($L22=TRUE(),"S1",IF($M22=TRUE(),"D"&MIN(4,INT(($S22-1)/DisplayCapacity)+1),IF($N22=TRUE(),"K1",IF($O22=TRUE(),"P1",IF($P22=TRUE(),"U1",IF($R22=TRUE(),"U1","W")))))))) -> S1 | U22: =IF($T22="","",$T22&"-"&COUNTIF($T$3:T22,$T22)) -> S1-2 | V22: =IF($B22="","",_xlfn.TEXTJOIN(" | ",TRUE(),IF($Q22=TRUE(),"Empty box - no physical device, verify status",""),IF(AND($P22=TRUE(),$L22=FALSE(),$M22=FALSE(),$N22=FALSE(),$O22=FALSE(),$Q22=FALSE()),"Speaker fault only - needs manual box assignment",""),IF(AND($R22=TRUE(),$L22=FALSE(),$M22=FALSE(),$N22=FALSE(),$O22=FALSE(),$P22=FALSE(),$Q22=FALSE()),"No fault detail given - needs technician inspection",""),IF(AND(COUNTIF($F$3:$F$252,$F22)>1,LOWER(TRIM($F22))<>"empty"),"Duplicate Serial No - verify device identity",""),IF((--$L22+--$M22+--$N22+--$O22+--$P22)>1,"Multiple fault types detected - review full details before repair",""))) -> Multiple fault types detected - review full details before repair | W22: 0
A23: 21 | B23: 46240.498 | C23: TX628 | D23: =IF($B23="","",IFERROR(VLOOKUP(TRIM($C23),ModelMap,2,FALSE()),TRIM($C23))) -> TX628 | E23: Anuradhapura | F23: 6160062164904 | G23: Working | J23: Colour | K23: =IF($B23="","",LOWER(TRIM($G23)&" | "&TRIM($H23)&" | "&TRIM($I23))) -> working | | | L23: =IF($B23="","",SUMPRODUCT(--ISNUMBER(SEARCH(SensorKW,$K23)))>0) -> FALSE | M23: =IF($B23="","",SUMPRODUCT(--ISNUMBER(SEARCH(DisplayKW,$K23)))>0) -> FALSE | N23: =IF($B23="","",SUMPRODUCT(--ISNUMBER(SEARCH(KeypadKW,$K23)))>0) -> FALSE | O23: =IF($B23="","",SUMPRODUCT(--ISNUMBER(SEARCH(PowerKW,$K23)))>0) -> FALSE | P23: =IF($B23="","",SUMPRODUCT(--ISNUMBER(SEARCH(SpeakerKW,$K23)))>0) -> FALSE | Q23: =IF($B23="","",OR(SUMPRODUCT(--ISNUMBER(SEARCH(EmptyKW,$K23)))>0,LOWER(TRIM($F23))="empty")) -> FALSE | R23: =IF($B23="","",OR(ISNUMBER(SEARCH("repair",$G23)),ISNUMBER(SEARCH("not working",$G23)))) -> FALSE | S23: =IF(AND($B23<>"",$M23=TRUE(),$L23=FALSE(),$Q23=FALSE()),COUNTIFS($M$3:$M23,TRUE(),$L$3:$L23,FALSE(),$Q$3:$Q23,FALSE()),"") | T23: =IF($B23="","",IF($Q23=TRUE(),"U1",IF($L23=TRUE(),"S1",IF($M23=TRUE(),"D"&MIN(4,INT(($S23-1)/DisplayCapacity)+1),IF($N23=TRUE(),"K1",IF($O23=TRUE(),"P1",IF($P23=TRUE(),"U1",IF($R23=TRUE(),"U1","W")))))))) -> W | U23: =IF($T23="","",$T23&"-"&COUNTIF($T$3:T23,$T23)) -> W-11 | V23: =IF($B23="","",_xlfn.TEXTJOIN(" | ",TRUE(),IF($Q23=TRUE(),"Empty box - no physical device, verify status",""),IF(AND($P23=TRUE(),$L23=FALSE(),$M23=FALSE(),$N23=FALSE(),$O23=FALSE(),$Q23=FALSE()),"Speaker fault only - needs manual box assignment",""),IF(AND($R23=TRUE(),$L23=FALSE(),$M23=FALSE(),$N23=FALSE(),$O23=FALSE(),$P23=FALSE(),$Q23=FALSE()),"No fault detail given - needs technician inspection",""),IF(AND(COUNTIF($F$3:$F$252,$F23)>1,LOWER(TRIM($F23))<>"empty"),"Duplicate Serial No - verify device identity",""),IF((--$L23+--$M23+--$N23+--$O23+--$P23)>1,"Multiple fault types detected - review full details before repair",""))) | W23: 0
A24: 22 | B24: 46240.503 | C24: X628 | D24: =IF($B24="","",IFERROR(VLOOKUP(TRIM($C24),ModelMap,2,FALSE()),TRIM($C24))) -> X628 | E24: Kappetipola | F24: CDQ9224660008 | G24: Working, Have to Repair | H24: No Sensor | J24: Colour | K24: =IF($B24="","",LOWER(TRIM($G24)&" | "&TRIM($H24)&" | "&TRIM($I24))) -> working, have to repair | no sensor | | L24: =IF($B24="","",SUMPRODUCT(--ISNUMBER(SEARCH(SensorKW,$K24)))>0) -> TRUE | M24: =IF($B24="","",SUMPRODUCT(--ISNUMBER(SEARCH(DisplayKW,$K24)))>0) -> FALSE | N24: =IF($B24="","",SUMPRODUCT(--ISNUMBER(SEARCH(KeypadKW,$K24)))>0) -> FALSE | O24: =IF($B24="","",SUMPRODUCT(--ISNUMBER(SEARCH(PowerKW,$K24)))>0) -> FALSE | P24: =IF($B24="","",SUMPRODUCT(--ISNUMBER(SEARCH(SpeakerKW,$K24)))>0) -> FALSE | Q24: =IF($B24="","",OR(SUMPRODUCT(--ISNUMBER(SEARCH(EmptyKW,$K24)))>0,LOWER(TRIM($F24))="empty")) -> FALSE | R24: =IF($B24="","",OR(ISNUMBER(SEARCH("repair",$G24)),ISNUMBER(SEARCH("not working",$G24)))) -> TRUE | S24: =IF(AND($B24<>"",$M24=TRUE(),$L24=FALSE(),$Q24=FALSE()),COUNTIFS($M$3:$M24,TRUE(),$L$3:$L24,FALSE(),$Q$3:$Q24,FALSE()),"") | T24: =IF($B24="","",IF($Q24=TRUE(),"U1",IF($L24=TRUE(),"S1",IF($M24=TRUE(),"D"&MIN(4,INT(($S24-1)/DisplayCapacity)+1),IF($N24=TRUE(),"K1",IF($O24=TRUE(),"P1",IF($P24=TRUE(),"U1",IF($R24=TRUE(),"U1","W")))))))) -> S1 | U24: =IF($T24="","",$T24&"-"&COUNTIF($T$3:T24,$T24)) -> S1-3 | V24: =IF($B24="","",_xlfn.TEXTJOIN(" | ",TRUE(),IF($Q24=TRUE(),"Empty box - no physical device, verify status",""),IF(AND($P24=TRUE(),$L24=FALSE(),$M24=FALSE(),$N24=FALSE(),$O24=FALSE(),$Q24=FALSE()),"Speaker fault only - needs manual box assignment",""),IF(AND($R24=TRUE(),$L24=FALSE(),$M24=FALSE(),$N24=FALSE(),$O24=FALSE(),$P24=FALSE(),$Q24=FALSE()),"No fault detail given - needs technician inspection",""),IF(AND(COUNTIF($F$3:$F$252,$F24)>1,LOWER(TRIM($F24))<>"empty"),"Duplicate Serial No - verify device identity",""),IF((--$L24+--$M24+--$N24+--$O24+--$P24)>1,"Multiple fault types detected - review full details before repair",""))) | W24: 0
A25: 23 | B25: 46240.512 | C25: X628-C | D25: =IF($B25="","",IFERROR(VLOOKUP(TRIM($C25),ModelMap,2,FALSE()),TRIM($C25))) -> X628-C | E25: Piliyandala 02 | F25: 6335172500115 | G25: Working | J25: Colour | K25: =IF($B25="","",LOWER(TRIM($G25)&" | "&TRIM($H25)&" | "&TRIM($I25))) -> working | | | L25: =IF($B25="","",SUMPRODUCT(--ISNUMBER(SEARCH(SensorKW,$K25)))>0) -> FALSE | M25: =IF($B25="","",SUMPRODUCT(--ISNUMBER(SEARCH(DisplayKW,$K25)))>0) -> FALSE | N25: =IF($B25="","",SUMPRODUCT(--ISNUMBER(SEARCH(KeypadKW,$K25)))>0) -> FALSE | O25: =IF($B25="","",SUMPRODUCT(--ISNUMBER(SEARCH(PowerKW,$K25)))>0) -> FALSE | P25: =IF($B25="","",SUMPRODUCT(--ISNUMBER(SEARCH(SpeakerKW,$K25)))>0) -> FALSE | Q25: =IF($B25="","",OR(SUMPRODUCT(--ISNUMBER(SEARCH(EmptyKW,$K25)))>0,LOWER(TRIM($F25))="empty")) -> FALSE | R25: =IF($B25="","",OR(ISNUMBER(SEARCH("repair",$G25)),ISNUMBER(SEARCH("not working",$G25)))) -> FALSE | S25: =IF(AND($B25<>"",$M25=TRUE(),$L25=FALSE(),$Q25=FALSE()),COUNTIFS($M$3:$M25,TRUE(),$L$3:$L25,FALSE(),$Q$3:$Q25,FALSE()),"") | T25: =IF($B25="","",IF($Q25=TRUE(),"U1",IF($L25=TRUE(),"S1",IF($M25=TRUE(),"D"&MIN(4,INT(($S25-1)/DisplayCapacity)+1),IF($N25=TRUE(),"K1",IF($O25=TRUE(),"P1",IF($P25=TRUE(),"U1",IF($R25=TRUE(),"U1","W")))))))) -> W | U25: =IF($T25="","",$T25&"-"&COUNTIF($T$3:T25,$T25)) -> W-12 | V25: =IF($B25="","",_xlfn.TEXTJOIN(" | ",TRUE(),IF($Q25=TRUE(),"Empty box - no physical device, verify status",""),IF(AND($P25=TRUE(),$L25=FALSE(),$M25=FALSE(),$N25=FALSE(),$O25=FALSE(),$Q25=FALSE()),"Speaker fault only - needs manual box assignment",""),IF(AND($R25=TRUE(),$L25=FALSE(),$M25=FALSE(),$N25=FALSE(),$O25=FALSE(),$P25=FALSE(),$Q25=FALSE()),"No fault detail given - needs technician inspection",""),IF(AND(COUNTIF($F$3:$F$252,$F25)>1,LOWER(TRIM($F25))<>"empty"),"Duplicate Serial No - verify device identity",""),IF((--$L25+--$M25+--$N25+--$O25+--$P25)>1,"Multiple fault types detected - review full details before repair",""))) | W25: 0
A26: 24 | B26: 46240.514 | C26: X628 | D26: =IF($B26="","",IFERROR(VLOOKUP(TRIM($C26),ModelMap,2,FALSE()),TRIM($C26))) -> X628 | E26: Mathale | F26: A5RN173460004 | G26: Working | J26: Colour | K26: =IF($B26="","",LOWER(TRIM($G26)&" | "&TRIM($H26)&" | "&TRIM($I26))) -> working | | | L26: =IF($B26="","",SUMPRODUCT(--ISNUMBER(SEARCH(SensorKW,$K26)))>0) -> FALSE | M26: =IF($B26="","",SUMPRODUCT(--ISNUMBER(SEARCH(DisplayKW,$K26)))>0) -> FALSE | N26: =IF($B26="","",SUMPRODUCT(--ISNUMBER(SEARCH(KeypadKW,$K26)))>0) -> FALSE | O26: =IF($B26="","",SUMPRODUCT(--ISNUMBER(SEARCH(PowerKW,$K26)))>0) -> FALSE | P26: =IF($B26="","",SUMPRODUCT(--ISNUMBER(SEARCH(SpeakerKW,$K26)))>0) -> FALSE | Q26: =IF($B26="","",OR(SUMPRODUCT(--ISNUMBER(SEARCH(EmptyKW,$K26)))>0,LOWER(TRIM($F26))="empty")) -> FALSE | R26: =IF($B26="","",OR(ISNUMBER(SEARCH("repair",$G26)),ISNUMBER(SEARCH("not working",$G26)))) -> FALSE | S26: =IF(AND($B26<>"",$M26=TRUE(),$L26=FALSE(),$Q26=FALSE()),COUNTIFS($M$3:$M26,TRUE(),$L$3:$L26,FALSE(),$Q$3:$Q26,FALSE()),"") | T26: =IF($B26="","",IF($Q26=TRUE(),"U1",IF($L26=TRUE(),"S1",IF($M26=TRUE(),"D"&MIN(4,INT(($S26-1)/DisplayCapacity)+1),IF($N26=TRUE(),"K1",IF($O26=TRUE(),"P1",IF($P26=TRUE(),"U1",IF($R26=TRUE(),"U1","W")))))))) -> W | U26: =IF($T26="","",$T26&"-"&COUNTIF($T$3:T26,$T26)) -> W-13 | V26: =IF($B26="","",_xlfn.TEXTJOIN(" | ",TRUE(),IF($Q26=TRUE(),"Empty box - no physical device, verify status",""),IF(AND($P26=TRUE(),$L26=FALSE(),$M26=FALSE(),$N26=FALSE(),$O26=FALSE(),$Q26=FALSE()),"Speaker fault only - needs manual box assignment",""),IF(AND($R26=TRUE(),$L26=FALSE(),$M26=FALSE(),$N26=FALSE(),$O26=FALSE(),$P26=FALSE(),$Q26=FALSE()),"No fault detail given - needs technician inspection",""),IF(AND(COUNTIF($F$3:$F$252,$F26)>1,LOWER(TRIM($F26))<>"empty"),"Duplicate Serial No - verify device identity",""),IF((--$L26+--$M26+--$N26+--$O26+--$P26)>1,"Multiple fault types detected - review full details before repair",""))) | W26: 0
A27: 25 | B27: 46240.517 | C27: X628-C | D27: =IF($B27="","",IFERROR(VLOOKUP(TRIM($C27),ModelMap,2,FALSE()),TRIM($C27))) -> X628-C | E27: Kesbewa 02 | F27: 6006165100002 | G27: Working, Have to Repair | H27: Sensor is not working | J27: Colour | K27: =IF($B27="","",LOWER(TRIM($G27)&" | "&TRIM($H27)&" | "&TRIM($I27))) -> working, have to repair | sensor is not working | | L27: =IF($B27="","",SUMPRODUCT(--ISNUMBER(SEARCH(SensorKW,$K27)))>0) -> TRUE | M27: =IF($B27="","",SUMPRODUCT(--ISNUMBER(SEARCH(DisplayKW,$K27)))>0) -> FALSE | N27: =IF($B27="","",SUMPRODUCT(--ISNUMBER(SEARCH(KeypadKW,$K27)))>0) -> FALSE | O27: =IF($B27="","",SUMPRODUCT(--ISNUMBER(SEARCH(PowerKW,$K27)))>0) -> FALSE | P27: =IF($B27="","",SUMPRODUCT(--ISNUMBER(SEARCH(SpeakerKW,$K27)))>0) -> FALSE | Q27: =IF($B27="","",OR(SUMPRODUCT(--ISNUMBER(SEARCH(EmptyKW,$K27)))>0,LOWER(TRIM($F27))="empty")) -> FALSE | R27: =IF($B27="","",OR(ISNUMBER(SEARCH("repair",$G27)),ISNUMBER(SEARCH("not working",$G27)))) -> TRUE | S27: =IF(AND($B27<>"",$M27=TRUE(),$L27=FALSE(),$Q27=FALSE()),COUNTIFS($M$3:$M27,TRUE(),$L$3:$L27,FALSE(),$Q$3:$Q27,FALSE()),"") | T27: =IF($B27="","",IF($Q27=TRUE(),"U1",IF($L27=TRUE(),"S1",IF($M27=TRUE(),"D"&MIN(4,INT(($S27-1)/DisplayCapacity)+1),IF($N27=TRUE(),"K1",IF($O27=TRUE(),"P1",IF($P27=TRUE(),"U1",IF($R27=TRUE(),"U1","W")))))))) -> S1 | U27: =IF($T27="","",$T27&"-"&COUNTIF($T$3:T27,$T27)) -> S1-4 | V27: =IF($B27="","",_xlfn.TEXTJOIN(" | ",TRUE(),IF($Q27=TRUE(),"Empty box - no physical device, verify status",""),IF(AND($P27=TRUE(),$L27=FALSE(),$M27=FALSE(),$N27=FALSE(),$O27=FALSE(),$Q27=FALSE()),"Speaker fault only - needs manual box assignment",""),IF(AND($R27=TRUE(),$L27=FALSE(),$M27=FALSE(),$N27=FALSE(),$O27=FALSE(),$P27=FALSE(),$Q27=FALSE()),"No fault detail given - needs technician inspection",""),IF(AND(COUNTIF($F$3:$F$252,$F27)>1,LOWER(TRIM($F27))<>"empty"),"Duplicate Serial No - verify device identity",""),IF((--$L27+--$M27+--$N27+--$O27+--$P27)>1,"Multiple fault types detected - review full details before repair",""))) -> Duplicate Serial No - verify device identity | W27: 0
A28: 26 | B28: 46240.521 | C28: X628 | D28: =IF($B28="","",IFERROR(VLOOKUP(TRIM($C28),ModelMap,2,FALSE()),TRIM($C28))) -> X628 | E28: Mathale 02 | F28: 6335183600001 | G28: Working | J28: Colour | K28: =IF($B28="","",LOWER(TRIM($G28)&" | "&TRIM($H28)&" | "&TRIM($I28))) -> working | | | L28: =IF($B28="","",SUMPRODUCT(--ISNUMBER(SEARCH(SensorKW,$K28)))>0) -> FALSE | M28: =IF($B28="","",SUMPRODUCT(--ISNUMBER(SEARCH(DisplayKW,$K28)))>0) -> FALSE | N28: =IF($B28="","",SUMPRODUCT(--ISNUMBER(SEARCH(KeypadKW,$K28)))>0) -> FALSE | O28: =IF($B28="","",SUMPRODUCT(--ISNUMBER(SEARCH(PowerKW,$K28)))>0) -> FALSE | P28: =IF($B28="","",SUMPRODUCT(--ISNUMBER(SEARCH(SpeakerKW,$K28)))>0) -> FALSE | Q28: =IF($B28="","",OR(SUMPRODUCT(--ISNUMBER(SEARCH(EmptyKW,$K28)))>0,LOWER(TRIM($F28))="empty")) -> FALSE | R28: =IF($B28="","",OR(ISNUMBER(SEARCH("repair",$G28)),ISNUMBER(SEARCH("not working",$G28)))) -> FALSE | S28: =IF(AND($B28<>"",$M28=TRUE(),$L28=FALSE(),$Q28=FALSE()),COUNTIFS($M$3:$M28,TRUE(),$L$3:$L28,FALSE(),$Q$3:$Q28,FALSE()),"") | T28: =IF($B28="","",IF($Q28=TRUE(),"U1",IF($L28=TRUE(),"S1",IF($M28=TRUE(),"D"&MIN(4,INT(($S28-1)/DisplayCapacity)+1),IF($N28=TRUE(),"K1",IF($O28=TRUE(),"P1",IF($P28=TRUE(),"U1",IF($R28=TRUE(),"U1","W")))))))) -> W | U28: =IF($T28="","",$T28&"-"&COUNTIF($T$3:T28,$T28)) -> W-14 | V28: =IF($B28="","",_xlfn.TEXTJOIN(" | ",TRUE(),IF($Q28=TRUE(),"Empty box - no physical device, verify status",""),IF(AND($P28=TRUE(),$L28=FALSE(),$M28=FALSE(),$N28=FALSE(),$O28=FALSE(),$Q28=FALSE()),"Speaker fault only - needs manual box assignment",""),IF(AND($R28=TRUE(),$L28=FALSE(),$M28=FALSE(),$N28=FALSE(),$O28=FALSE(),$P28=FALSE(),$Q28=FALSE()),"No fault detail given - needs technician inspection",""),IF(AND(COUNTIF($F$3:$F$252,$F28)>1,LOWER(TRIM($F28))<>"empty"),"Duplicate Serial No - verify device identity",""),IF((--$L28+--$M28+--$N28+--$O28+--$P28)>1,"Multiple fault types detected - review full details before repair",""))) | W28: 0
A29: 27 | B29: 46240.524 | C29: X628-C | D29: =IF($B29="","",IFERROR(VLOOKUP(TRIM($C29),ModelMap,2,FALSE()),TRIM($C29))) -> X628-C | E29: Seeduwa | F29: CDQ9193960103 | G29: Working, Have to Repair | H29: Sensor is not working and also have power issue some times | J29: Colour | K29: =IF($B29="","",LOWER(TRIM($G29)&" | "&TRIM($H29)&" | "&TRIM($I29))) -> working, have to repair | sensor is not working and also have power issue some times | | L29: =IF($B29="","",SUMPRODUCT(--ISNUMBER(SEARCH(SensorKW,$K29)))>0) -> TRUE | M29: =IF($B29="","",SUMPRODUCT(--ISNUMBER(SEARCH(DisplayKW,$K29)))>0) -> FALSE | N29: =IF($B29="","",SUMPRODUCT(--ISNUMBER(SEARCH(KeypadKW,$K29)))>0) -> FALSE | O29: =IF($B29="","",SUMPRODUCT(--ISNUMBER(SEARCH(PowerKW,$K29)))>0) -> TRUE | P29: =IF($B29="","",SUMPRODUCT(--ISNUMBER(SEARCH(SpeakerKW,$K29)))>0) -> FALSE | Q29: =IF($B29="","",OR(SUMPRODUCT(--ISNUMBER(SEARCH(EmptyKW,$K29)))>0,LOWER(TRIM($F29))="empty")) -> FALSE | R29: =IF($B29="","",OR(ISNUMBER(SEARCH("repair",$G29)),ISNUMBER(SEARCH("not working",$G29)))) -> TRUE | S29: =IF(AND($B29<>"",$M29=TRUE(),$L29=FALSE(),$Q29=FALSE()),COUNTIFS($M$3:$M29,TRUE(),$L$3:$L29,FALSE(),$Q$3:$Q29,FALSE()),"") | T29: =IF($B29="","",IF($Q29=TRUE(),"U1",IF($L29=TRUE(),"S1",IF($M29=TRUE(),"D"&MIN(4,INT(($S29-1)/DisplayCapacity)+1),IF($N29=TRUE(),"K1",IF($O29=TRUE(),"P1",IF($P29=TRUE(),"U1",IF($R29=TRUE(),"U1","W")))))))) -> S1 | U29: =IF($T29="","",$T29&"-"&COUNTIF($T$3:T29,$T29)) -> S1-5 | V29: =IF($B29="","",_xlfn.TEXTJOIN(" | ",TRUE(),IF($Q29=TRUE(),"Empty box - no physical device, verify status",""),IF(AND($P29=TRUE(),$L29=FALSE(),$M29=FALSE(),$N29=FALSE(),$O29=FALSE(),$Q29=FALSE()),"Speaker fault only - needs manual box assignment",""),IF(AND($R29=TRUE(),$L29=FALSE(),$M29=FALSE(),$N29=FALSE(),$O29=FALSE(),$P29=FALSE(),$Q29=FALSE()),"No fault detail given - needs technician inspection",""),IF(AND(COUNTIF($F$3:$F$252,$F29)>1,LOWER(TRIM($F29))<>"empty"),"Duplicate Serial No - verify device identity",""),IF((--$L29+--$M29+--$N29+--$O29+--$P29)>1,"Multiple fault types detected - review full details before repair",""))) -> Multiple fault types detected - review full details before repair | W29: 0
